Workbook

Sheet 0. DLR Source Data
B2: Digital Realty (DLR) — Source Data & Reconciliation Anchors
B3: Sourced from DLR public releases (see Sources). These are ANCHORS to verify against the FY2025 10-K and Q4-2025 supplemental — not final inputs.
B4: Net income carries large non-core gains (e.g., Q2'25 +$2.94/sh); treat Core FFO as the headline operating metric.
B6: FY2025 REPORTED ACTUALS (reported basis, fully diluted)
B7: Total revenue (FY2025) | C7: $6.11 B | D7: ACTUAL FY2025 (+10% YoY). Q1 1.408+Q2 1.493+Q3 1.577+Q4 1.632
B8: Adjusted EBITDA (FY2025) | C8: $3.34 B | D8: ACTUAL. Q1 791+Q2 823+Q3 868+Q4 857 ($M)
B9: Net income avail. to common / share | C9: $3.45–$3.55 | D9: FY guidance; includes large Q2'25 gain of $2.94/sh
B10: FFO / share (FY2025, reported) | C10: ~$6.96 | D10: Sum: 1.67 + 1.75 + 1.65 + 1.89
B11: Core FFO / share (FY2025, reported) | C11: ~$7.39 | D11: Sum: 1.77 + 1.87 + 1.89 + 1.86 ← HEADLINE METRIC
B12: Diluted shares (approx.) | C12: ~345–347 M | D12: Derived: Q3 FFO $570M ÷ $1.65; Q2 NIAC $1.02B ÷ $2.94
B13: Quarterly Core FFO / share | C13: 1.77 / 1.87 / 1.89 / 1.86 | D13: Q1 / Q2 / Q3 (record) / Q4 2025
B14: Quarterly revenue | C14: $1.41/1.49/1.58/1.63 B | D14: Q1-Q4 2025 — SEC 8-K actuals
B15: Quarterly Adjusted EBITDA | C15: 791/823/868/857 ($M) | D15: Q1-Q4 2025 Adj EBITDA — SEC 8-K
B17: BALANCE SHEET / LEVERAGE (as of mid-2025 unless noted)
B18: Total debt (6/30/25) | C18: $18.23 B (9/30/25) | D18: $17.4B unsec+$0.8B sec. 12/31/24: $16.71B
B19: Net debt / Adjusted EBITDA | C19: 4.9x (Q3'25) | D19: 5.1x at Q2'25 — deleveraging trend
B20: Total assets / portfolio (Q4'25) | C20: $48.73 B (9/30/25) | D20: Total assets Q3 8-K; 12/31/24: $45.28B
B21: Debt / equity | C21: 0.74 | D21: Q4'25
B22: Price / book (Q4'25) | C22: 2.39x | D22: Down from 2.65x in Q3'25
B23: Fixed charge coverage (Q3'25) | C23: 4.6x | D23: Adj. EBITDA ÷ (interest + cap. interest + pref. divs)
B24: Q3'25 interest detail ($M) | C24: Int 114 / CapInt 33 / Pref 10 | D24: GAAP interest / capitalized interest / preferred divs
B25: Credit ratings | C25: BBB+ / Baa2 / BBB | D25: S&P/Moody’s/Fitch — all Stable (Q3 8-K)
B26: DIVIDEND
B27: Common dividend per share | C27: $1.22/qtr = $4.88/yr | D27: Held flat YoY; yield ~2.6–3.2%
B28: Shares + units (9/30/25) | C28: 349.2 M | D28: 343.0M common + 6.2M OP units (Q3 8-K)
B29: 2026 GUIDANCE (introduced with Q4'25 results, 2/5/2026)
B30: Core FFO / share — 2026E | C30: $7.90 – $8.00 | D30: Reported & constant-currency basis
B32: DLR's EXACT AFFO BRIDGE — Core FFO → AFFO (per DLR Q3'25 release)
B33: DLR computes AFFO by adjusting CORE FFO (not NAREIT FFO) for the following ten items:
B34: (i) non-real estate depreciation
B35: (ii) amortization of deferred financing costs
B36: (iii) amortization of debt discount / premium
B37: (iv) non-cash stock-based compensation
B38: (v) straight-line rental revenue
B39: (vi) straight-line rental expense
B40: (vii) above- / below-market rent amortization
B41: (viii) deferred tax expense / (benefit)
B42: (ix) leasing compensation & internal lease commissions
B43: (x) recurring capital expenditures
... B48: OPERATING / LEASING CONTEXT (FY2025)
...

Sheet 1. Assumptions
A1: DLR | REIT Three-Statement Model — Assumptions Dashboard
A2: All driver inputs live here. Linked from all other tabs. Replace blue cells with current data.
B4: 2021 | C4: 2022 | D4: 2023 | E4: 2024 | F4: 2025 | G4: 2026 | H4: 2027 | I4: 2028 | J4: 2029 | K4: 2030 | L4: Notes / Source
B5: A | C5: A | D5: A | E5: A | F5: A | G5: E | H5: E | I5: E | J5: E | K5: E
A7: MACRO ASSUMPTIONS
A8: 10-Yr Treasury yield (Rf) | B8: 0.045 | L8: Source: U.S. Treasury, current
A9: Equity risk premium (ERP) | B9: 0.055 | L9: Source: Damodaran, latest
A10: Beta (vs. XLRE) | B10: 1.1 | L10: Source: Bloomberg or compute 60M weekly
A11: Long-term inflation | B11: 0.025 | L11: Source: Fed long-run projection
A12: Terminal growth (g) | B12: 0.025
A15: OPERATING ASSUMPTIONS — Same-Property NOI Growth
A16: Hyperscale — Americas | G16: 0.03 | H16: 0.04 | I16: 0.05 | J16: 0.045 | K16: 0.04
A17: Hyperscale — EMEA | G17: 0.025 | H17: 0.035 | I17: 0.045 | J17: 0.04 | K17: 0.035
A18: Hyperscale — APAC | G18: 0.04 | H18: 0.05 | I18: 0.06 | J18: 0.055 | K18: 0.05
A19: Colocation — global | G19: 0.02 | H19: 0.025 | I19: 0.03 | J19: 0.03 | K19: 0.025
A22: CAPITAL ASSUMPTIONS
A23: Development capex ($M) | G23: 800 | H23: 1000 | I23: 1200 | J23: 1300 | K23: 1100 | L23: Source: Tab 4 — Pipeline
A24: Recurring capex (% of revenue) | G24: 0.04 | H24: 0.04 | I24: 0.04 | J24: 0.04 | K24: 0.04 | L24: Industry: 3-5%
A25: Target Net Debt / EBITDA | G25: 5 | H25: 5 | I25: 5 | J25: 5 | K25: 5 | L25: Mgmt target
A26: Dividend payout (% of AFFO) | G26: 0.68 | H26: 0.68 | I26: 0.68 | J26: 0.68 | K26: 0.68 | L26: Mgmt policy
A27: Weighted avg cost of debt | G27: 0.042 | H27: 0.042 | I27: 0.042 | J27: 0.042 | K27: 0.042
A28: Core FFO/share growth (E) | G28: 0.075 | H28: 0.06 | I28: 0.05 | J28: 0.05 | K28: 0.04 | L28: YOUR input. 2026 ≈ guidance (+7-8%); taper after. Drives DCF.
A30: VALUATION ASSUMPTIONS
A31: Cost of equity (CAPM) | B31: =B8+B10*B9 -> 0.1055 | L31: Rf + Beta × ERP
A32: After-tax cost of debt | B32: 0.045 | L32: REITs effectively non-taxed at corp level
A33: Target debt weight | B33: 0.45 | L33: Market-value weights
A34: WACC | B34: =(1-B33)*B31+B33*B32 -> 0.078275 | L34: Blended
A35: Terminal exit cap rate | B35: 0.065 | L35: Current market cap + 50bps
A36: NAV cap rate — Hyperscale | B36: 0.065 | L36: CBRE / Green Street current
A37: NAV cap rate — Colocation | B37: 0.06
A38: AFFO / Core FFO conversion | B38: 0.88 | L38: YOUR input. DLR AFFO historically ~0.85-0.92 of Core FFO; verify in 10-K.
A39: Dev capex debt-funded % | B39: 0.5 | L39: YOUR input. Share of dev capex funded by new debt (rest by retained AFFO).
A40: DLR ANCHORS (see '0. DLR Source Data')
A41: 2026E Core FFO/share guidance | B41: $7.90–$8.00
A42: FY2025 reported Core FFO/share | B42: ~$7.39
A43: Annual dividend / share | B43: $4.88
A44: Net debt / Adj. EBITDA (actual) | B44: 4.9x (Q3'25)

Sheet 2. Historicals
A1: Historical Financials — 5 Years
A2: US$ in millions, FYE Dec 31. Source: DLR 10-K filings. Blue cells = hardcoded actuals from filings.
B4: 2021 | C4: 2022 | D4: 2023 | E4: 2024 | F4: 2025 | G4: Source / Notes
B5: A | C5: A | D5: A | E5: A | F5: A
A7: INCOME STATEMENT
A9: Total revenue | F9: 6110 | G9: FY2025 sourced (SEC 8-K + Q4 release). Detail lines from 10-K.
A10: Rental revenue | F10: [from 10-K]
A11: Tenant reimbursements | F11: [from 10-K]
A12: Interconnection & other | F12: [from 10-K]
A13: Property operating expenses | F13: [from 10-K]
A14: Real estate taxes | F14: [from 10-K]
A15: Property NOI
A16: General & administrative | F16: [from 10-K]
A17: Depreciation & amortization — RE | F17: [from 10-K]
A18: Depreciation & amortization — other | F18: [from 10-K]
A19: Operating income
A20: Interest expense, net | F20: [from 10-K]
A21: Other income / (expense) | F21: [from 10-K]
A22: Pre-tax income
A23: Income tax | F23: [from 10-K]
A24: Gain (loss) on sale of real estate | F24: [from 10-K]
A25: Impairment of real estate | F25: [from 10-K]
A26: Net income | F26: [from 10-K]
A27: Less: NCI / preferred dividends | F27: [from 10-K]
A28: Net income to common shareholders | F28: [from 10-K]
A29: Diluted shares outstanding (M) | F29: 346
A30: EPS — diluted | F30: [from 10-K]
A35: BALANCE SHEET
A37: Investments in real estate, gross | E37: 35402 | F37: 39375 | G37: 12/31/24 sourced; FY2025 col = 9/30/25 interim — update to 12/31/25 from 10-K.
A38: Less: accumulated depreciation | F38: [from 10-K]
A39: Investments in real estate, net | F39: [from 10-K]
A40: Construction in progress | F40: [from 10-K]
A41: Cash & equivalents | E41: 0 | F41: 0
A42: Accounts receivable | F42: [from 10-K]
A43: Other assets | F43: [from 10-K]
A44: Total assets | E44: 45284 | F44: 48729
A45: Mortgages & loans payable | F45: [from 10-K]
A46: Unsecured senior notes | E46: 16714 | F46: 18225
A47: Unsecured credit facility | F47: [from 10-K]
A48: Accounts payable & accrued | F48: [from 10-K]
...

Sheet 3. Segment Build
A1: Segment Revenue & NOI Build
A2: By segment × region. Historical 5Y from filings, forecast 5Y driven by SP-NOI growth assumptions.
A3: FY2025 total $6,110M is SOURCED; segment split F8:F11 is ILLUSTRATIVE — replace from 10-K.
B4: 2021 | C4: 2022 | D4: 2023 | E4: 2024 | F4: 2025 | G4: 2026 | H4: 2027 | I4: 2028 | J4: 2029 | K4: 2030
B5: A | C5: A | D5: A | E5: A | F5: A | G5: E | H5: E | I5: E | J5: E | K5: E
A7: REVENUE BY SEGMENT
A8: Hyperscale — Americas | F8: 2900 | G8: =F8*(1+'1. Assumptions'!$G$16) -> 2987 | H8: =G8*(1+'1. Assumptions'!$H$16) -> 3106.48 | I8: =H8*(1+'1. Assumptions'!$I$16) -> 3261.804 | J8: =I8*(1+'1. Assumptions'!$J$16) -> 3408.5852 | K8: =J8*(1+'1. Assumptions'!$K$16) -> 3544.9286
A9: Hyperscale — EMEA | F9: 1650 | G9: =F9*(1+'1. Assumptions'!$G$17) -> 1691.25 | H9: =G9*(1+'1. Assumptions'!$H$17) -> 1750.4437 | I9: =H9*(1+'1. Assumptions'!$I$17) -> 1829.2137 | J9: =I9*(1+'1. Assumptions'!$J$17) -> 1902.3823 | K9: =J9*(1+'1. Assumptions'!$K$17) -> 1968.9656
A10: Hyperscale — APAC | F10: 950 | G10: =F10*(1+'1. Assumptions'!$G$18) -> 988 | H10: =G10*(1+'1. Assumptions'!$H$18) -> 1037.4 | I10: =H10*(1+'1. Assumptions'!$I$18) -> 1099.644 | J10: =I10*(1+'1. Assumptions'!$J$18) -> 1160.1244 | K10: =J10*(1+'1. Assumptions'!$K$18) -> 1218.1306
A11: Colocation — global | F11: 610 | G11: =F11*(1+'1. Assumptions'!$G$19) -> 622.2 | H11: =G11*(1+'1. Assumptions'!$H$19) -> 637.755 | I11: =H11*(1+'1. Assumptions'!$I$19) -> 656.88765 | J11: =I11*(1+'1. Assumptions'!$J$19) -> 676.59428 | K11: =J11*(1+'1. Assumptions'!$K$19) -> 693.50914
A13: Total revenue | B13: =SUM(B8:B11) -> 0 | C13: =SUM(C8:C11) -> 0 | D13: =SUM(D8:D11) -> 0 | E13: =SUM(E8:E11) -> 0 | F13: =SUM(F8:F11) -> 6110 | G13: =SUM(G8:G11) -> 6288.45 | H13: =SUM(H8:H11) -> 6532.0787 | I13: =SUM(I8:I11) -> 6847.5494 | ... K13: =SUM(K8:K11) -> 7425.534
A16: NOI BY SEGMENT (assume 60% NOI margin)
A17: Hyperscale — Americas | B17: =B8*0.6 -> 0 | C17: =C8*0.6 -> 0 | D17: =D8*0.6 -> 0 | E17: =E8*0.6 -> 0 | F17: =F8*0.6 -> 1740 | G17: =G8*0.6 -> 1792.2 | H17: =H8*0.6 -> 1863.888 | I17: =I8*0.6 -> 1957.0824 | ... K17: =K8*0.6 -> 2126.9572
A18: Hyperscale — EMEA | B18: =B9*0.6 -> 0 | C18: =C9*0.6 -> 0 | D18: =D9*0.6 -> 0 | E18: =E9*0.6 -> 0 | F18: =F9*0.6 -> 990 | G18: =G9*0.6 -> 1014.75 | H18: =H9*0.6 -> 1050.2662 | I18: =I9*0.6 -> 1097.5282 | ... K18: =K9*0.6 -> 1181.3794
A19: Hyperscale — APAC | B19: =B10*0.6 -> 0 | C19: =C10*0.6 -> 0 | D19: =D10*0.6 -> 0 | E19: =E10*0.6 -> 0 | F19: =F10*0.6 -> 570 | G19: =G10*0.6 -> 592.8 | H19: =H10*0.6 -> 622.44 | I19: =I10*0.6 -> 659.7864 | ... K19: =K10*0.6 -> 730.87838
A20: Colocation — global | B20: =B11*0.6 -> 0 | C20: =C11*0.6 -> 0 | D20: =D11*0.6 -> 0 | E20: =E11*0.6 -> 0 | F20: =F11*0.6 -> 366 | G20: =G11*0.6 -> 373.32 | H20: =H11*0.6 -> 382.653 | I20: =I11*0.6 -> 394.13259 | ... K20: =K11*0.6 -> 416.10548
A22: Total property NOI | B22: =SUM(B17:B20) -> 0 | C22: =SUM(C17:C20) -> 0 | D22: =SUM(D17:D20) -> 0 | E22: =SUM(E17:E20) -> 0 | F22: =SUM(F17:F20) -> 3666 | G22: =SUM(G17:G20) -> 3773.07 | H22: =SUM(H17:H20) -> 3919.2472 | I22: =SUM(I17:I20) -> 4108.5296 | ... K22: =SUM(K17:K20) -> 4455.3204

Sheet 4. Dev Pipeline
A1: Development Pipeline Rollforward
A2: Each project: location, MW, expected stabilization, capital deployed, capital remaining, yield-on-cost.
A4: Project | B4: Region | C4: MW | D4: Stabilization | E4: Total cost ($M) | F4: Spent to date | G4: Remaining | H4: Yield-on-cost | I4: Stabilized NOI ($M) | J4: Notes
A6: [Add projects from DLR 10-K Schedule of Development Pipeline]
A7: Project Alpha (placeholder) | B7: Americas | C7: 48 | D7: Q3 2026 | E7: 450 | F7: 280 | G7: 170 | H7: 0.085 | I7: =E7*H7 -> 38.25
A20: TOTALS | E20: =SUM(E7:E19) -> 450 | F20: =SUM(F7:F19) -> 280 | G20: =SUM(G7:G19) -> 170 | I20: =SUM(I7:I19) -> 38.25

Sheet 5. Income Statement
A1: Income Statement — Historical + 5-Year Forecast
A2: Historical: green-linked from Tab 2. Forecast: green-linked from Tab 3 (revenue/NOI) and Tab 1 (other drivers).
A3: Revenue & Property NOI are wired (from Tab 3). Expense/D&A/NI lines: historical from 10-K, forecast built from your operating assumptions. Valuation runs off Core FFO (Tab 8/9).
B4: 2021 | C4: 2022 | D4: 2023 | E4: 2024 | F4: 2025 | G4: 2026 | H4: 2027 | I4: 2028 | J4: 2029 | K4: 2030
B5: A | C5: A | D5: A | E5: A | F5: A | G5: E | H5: E | I5: E | J5: E | K5: E
A7: Total revenue | F7: ='3. Segment Build'!F13 -> 6110 | G7: ='3. Segment Build'!G13 -> 6288.45 | H7: ='3. Segment Build'!H13 -> 6532.0787 | I7: ='3. Segment Build'!I13 -> 6847.5494 | J7: ='3. Segment Build'!J13 -> 7147.6861 | K7: ='3. Segment Build'!K13 -> 7425.534
A8: Property operating expenses | G8: =-(G7-G10) -> -2515.38 | H8: =-(H7-H10) -> -2612.8315 | I8: =-(I7-I10) -> -2739.0197 | J8: =-(J7-J10) -> -2859.0745 | K8: =-(K7-K10) -> -2970.2136
A9: Real estate taxes | G9: 0 | H9: 0 | I9: 0 | J9: 0 | K9: 0
A10: Property NOI | F10: ='3. Segment Build'!F22 -> 3666 | G10: ='3. Segment Build'!G22 -> 3773.07 | H10: ='3. Segment Build'!H22 -> 3919.2472 | I10: ='3. Segment Build'!I22 -> 4108.5296 | J10: ='3. Segment Build'!J22 -> 4288.6117 | K10: ='3. Segment Build'!K22 -> 4455.3204
A11: G&A expense | F11: [10-K] | G11: [build] | H11: [build] | I11: [build] | J11: [build] | K11: [build]
A12: D&A — real estate | F12: [10-K] | G12: [build] | H12: [build] | I12: [build] | J12: [build] | K12: [build]
A13: D&A — other | F13: [10-K] | G13: [build] | H13: [build] | I13: [build] | J13: [build] | K13: [build]
A14: Operating income | F14: [10-K] | G14: [build] | H14: [build] | I14: [build] | J14: [build] | K14: [build]
A15: Interest expense, net | F15: [10-K] | G15: [build] | H15: [build] | I15: [build] | J15: [build] | K15: [build]
A16: Other income / (expense) | F16: [10-K] | G16: [build] | H16: [build] | I16: [build] | J16: [build] | K16: [build]
A17: Pre-tax income | F17: [10-K] | G17: [build] | H17: [build] | I17: [build] | J17: [build] | K17: [build]
A18: Income tax | F18: [10-K] | G18: [build] | H18: [build] | I18: [build] | J18: [build] | K18: [build]
A19: Gain (loss) on sale of RE | F19: [10-K] | G19: [build] | H19: [build] | I19: [build] | J19: [build] | K19: [build]
A20: Impairment of real estate | F20: [10-K] | G20: [build] | H20: [build] | I20: [build] | J20: [build] | K20: [build]
A21: Net income | F21: [10-K] | G21: [build] | H21: [build] | I21: [build] | J21: [build] | K21: [build]
A22: Less: NCI / preferred dividends | F22: [10-K] | G22: [build] | H22: [build] | I22: [build] | J22: [build] | K22: [build]
A23: Net income to common | F23: [10-K] | G23: [build] | H23: [build] | I23: [build] | J23: [build] | K23: [build]
A24: Diluted shares outstanding (M) | F24: ='2. Historicals'!F29 -> 346 | G24: ='2. Historicals'!$F$29 -> 346 | H24: ='2. Historicals'!$F$29 -> 346 | I24: ='2. Historicals'!$F$29 -> 346 | J24: ='2. Historicals'!$F$29 -> 346 | K24: ='2. Historicals'!$F$29 -> 346

Sheet 6. Balance Sheet
A1: Balance Sheet — Historical + 5-Year Forecast
A2: Real estate rolls forward by capex & dispositions. Debt schedule embedded rows 60-90.
B4: 2021 | C4: 2022 | D4: 2023 | E4: 2024 | F4: 2025 | G4: 2026 | H4: 2027 | I4: 2028 | J4: 2029 | K4: 2030
B5: A | C5: A | D5: A | E5: A | F5: A | G5: E | H5: E | I5: E | J5: E | K5: E
A7: ASSETS
A8: Real estate, gross
A9: Less: accumulated depreciation
A10: Real estate, net
A11: Construction in progress
A12: Cash & equivalents
A13: Accounts receivable
A14: Other assets
A15: TOTAL ASSETS
A17: LIABILITIES
A18: Mortgages payable
A19: Unsecured senior notes
... A36: Check (Total Assets - Total L+E)

Sheet 7. Cash Flow
A1: Cash Flow Statement — Historical + 5-Year Forecast
A2: CFO derives from NI + D&A + WC. CFI links capex from Tab 4. CFF links from Tab 1 + Tab 6.
B4: 2021 | C4: 2022 | D4: 2023 | E4: 2024 | F4: 2025 | G4: 2026 | H4: 2027 | I4: 2028 | J4: 2029 | K4: 2030
B5: A | C5: A | D5: A | E5: A | F5: A | G5: E | H5: E | I5: E | J5: E | K5: E
A7: CASH FROM OPERATIONS
A8: Net income
A9: + D&A (total)
A10: + Stock-based comp
A11: + Straight-line rent adjustment
A12: +/- Working capital
A13: - Gain on sales of RE
A14: CFO
A16: CASH FROM INVESTING
A17: Development & acquisition capex
A18: Recurring capex
A19: Proceeds from dispositions
... A32: Ending cash (should tie to BS)

Sheet 8. FFO-AFFO
A1: FFO / AFFO Reconciliation
A2: The critical REIT-specific metrics. DLR headlines CORE FFO and bridges AFFO from it — reconcile line-by-line to management's reported figures (within 1–2% is institutional fluency).
B4: 2021 | C4: 2022 | D4: 2023 | E4: 2024 | F4: 2025 | G4: 2026 | H4: 2027 | I4: 2028 | J4: 2029 | K4: 2030 | M4: FY2025 REPORTED (sourced — reconcile bridge to these)
B5: A | C5: A | D5: A | E5: A | F5: A | G5: E | H5: E | I5: E | J5: E | K5: E | M5: Core FFO / share | N5: 7.39
M6: NAREIT FFO / share | N6: 6.96
A7: FFO RECONCILIATION (NAREIT) | M7: Dividend / share | N7: 4.88
M8: Diluted shares (M) | N8: 346
A9: Net income | M9: Implied Core FFO ($M) | N9: =N5*N8 -> 2556.94
A10: (+) Real estate D&A | M10: 2026E Core FFO/sh (guid mid) | N10: 7.95
A11: (+) Impairments on depreciable RE
A12: (-) Gains on sales of depreciable RE
A13: (+/-) Proportionate JV adjustments
A14: (+/-) NCI adjustments
A16: FFO (NAREIT) | B16: =SUM(B9:B14) -> 0 | C16: =SUM(C9:C14) -> 0 | D16: =SUM(D9:D14) -> 0 | E16: =SUM(E9:E14) -> 0 | F16: =SUM(F9:F14) -> 0 | G16: =SUM(G9:G14) -> 0 | H16: =SUM(H9:H14) -> 0 | I16: =SUM(I9:I14) -> 0 | ... K16: =SUM(K9:K14) -> 0
A18: FFO (NAREIT) per diluted share | B18: =IFERROR(B16/'5. Income Statement'!B24,0) -> 0 | C18: =IFERROR(C16/'5. Income Statement'!C24,0) -> 0 | D18: =IFERROR(D16/'5. Income Statement'!D24,0) -> 0 | E18: =IFERROR(E16/'5. Income Statement'!E24,0) -> 0 | F18: =IFERROR(F16/'5. Income Statement'!F24,0) -> 0 | G18: =IFERROR(G16/'5. Income Statement'!G24,0) -> 0 | H18: =IFERROR(H16/'5. Income Statement'!H24,0) -> 0 | I18: =IFERROR(I16/'5. Income Statement'!I24,0) -> 0 | ... K18: =IFERROR(K16/'5. Income Statement'!K24,0) -> 0
A21: CORE FFO RECONCILIATION (DLR headline metric)
A23: FFO (NAREIT) | B23: =B16 -> 0 | C23: =C16 -> 0 | D23: =D16 -> 0 | E23: =E16 -> 0 | F23: =F16 -> 0 | G23: =G16 -> 0 | H23: =H16 -> 0 | I23: =I16 -> 0 | ... K23: =K16 -> 0
A24: (+) Transaction & integration costs
A25: (+/-) (Gain)/loss on debt extinguishment
A26: (+) Severance & equity acceleration
A27: (+/-) Other non-core items
A29: CORE FFO | B29: =SUM(B23:B27) -> 0 | C29: =SUM(C23:C27) -> 0 | D29: =SUM(D23:D27) -> 0 | E29: =SUM(E23:E27) -> 0 | F29: =SUM(F23:F27) -> 0 | G29: =SUM(G23:G27) -> 0 | H29: =SUM(H23:H27) -> 0 | I29: =SUM(I23:I27) -> 0 | ... K29: =SUM(K23:K27) -> 0
A30: Core FFO per diluted share | B30: =IFERROR(B29/'5. Income Statement'!B24,0) -> 0 | C30: =IFERROR(C29/'5. Income Statement'!C24,0) -> 0 | D30: =IFERROR(D29/'5. Income Statement'!D24,0) -> 0 | E30: =IFERROR(E29/'5. Income Statement'!E24,0) -> 0 | F30: =IFERROR(F29/'5. Income Statement'!F24,0) -> 0 | G30: =IFERROR(G29/'5. Income Statement'!G24,0) -> 0 | H30: =IFERROR(H29/'5. Income Statement'!H24,0) -> 0 | I30: =IFERROR(I29/'5. Income Statement'!I24,0) -> 0 | ... K30: =IFERROR(K29/'5. Income Statement'!K24,0) -> 0
A33: AFFO RECONCILIATION (bridged from Core FFO — DLR 10-item method)
A35: Core FFO | B35: =B29 -> 0 | C35: =C29 -> 0 | D35: =D29 -> 0 | E35: =E29 -> 0 | F35: =F29 -> 0 | G35: =G29 -> 0 | H35: =H29 -> 0 | I35: =I29 -> 0 | ... K35: =K29 -> 0
A36: (+) Non-real estate depreciation
A37: (+) Amort. of deferred financing costs
A38: (+/-) Amort. of debt discount/premium
A39: (+) Non-cash stock-based compensation
A40: (-) Straight-line rental revenue
A41: (+) Straight-line rental expense
A42: (+/-) Above/below-market rent amort.
A43: (+/-) Deferred tax
A44: (+) Leasing comp & internal lease commissions
A45: (-) Recurring capex
A47: AFFO | B47: =SUM(B35:B45) -> 0 | C47: =SUM(C35:C45) -> 0 | D47: =SUM(D35:D45) -> 0 | E47: =SUM(E35:E45) -> 0 | F47: =SUM(F35:F45) -> 0 | G47: =SUM(G35:G45) -> 0 | H47: =SUM(H35:H45) -> 0 | I47: =SUM(I35:I45) -> 0 | ... K47: =SUM(K35:K45) -> 0
A49: AFFO per diluted share | B49: =IFERROR(B47/'5. Income Statement'!B24,0) -> 0 | C49: =IFERROR(C47/'5. Income Statement'!C24,0) -> 0 | D49: =IFERROR(D47/'5. Income Statement'!D24,0) -> 0 | E49: =IFERROR(E47/'5. Income Statement'!E24,0) -> 0 | F49: =IFERROR(F47/'5. Income Statement'!F24,0) -> 0 | G49: =IFERROR(G47/'5. Income Statement'!G24,0) -> 0 | H49: =IFERROR(H47/'5. Income Statement'!H24,0) -> 0 | I49: =IFERROR(I47/'5. Income Statement'!I24,0) -> 0 | ... K49: =IFERROR(K47/'5. Income Statement'!K24,0) -> 0
A51: Common dividend per share | F51: 4.88
A53: AFFO payout ratio | B53: =IFERROR(B51/B49,0) -> 0 | C53: =IFERROR(C51/C49,0) -> 0 | D53: =IFERROR(D51/D49,0) -> 0 | E53: =IFERROR(E51/E49,0) -> 0 | F53: =IFERROR(F51/F49,0) -> 0 | G53: =IFERROR(G51/G49,0) -> 0 | H53: =IFERROR(H51/H49,0) -> 0 | I53: =IFERROR(I51/I49,0) -> 0 | ... K53: =IFERROR(K51/K49,0) -> 0
A56: DLR RECONCILIATION GUIDANCE — see '0. DLR Source Data' for full detail
...

Sheet 9. Valuation
A1: Valuation — DCF + NAV
A2: Two side-by-side approaches. Conclusion at bottom: DCF target vs. NAV target vs. current trading price.
A7: DCF VALUATION
A9: WACC build
A10: Cost of equity | B10: ='1. Assumptions'!B31 -> 0.1055
A11: After-tax cost of debt | B11: ='1. Assumptions'!B32 -> 0.045
A12: WACC | B12: ='1. Assumptions'!B34 -> 0.078275
A15: FCFE projection
B16: 2026 | C16: 2027 | D16: 2028 | E16: 2029 | F16: 2030 | G16: Terminal
A17: Core FFO / share | B17: ='8. FFO-AFFO'!$N$5*(1+'1. Assumptions'!$G$28) -> 7.94425 | C17: =B17*(1+'1. Assumptions'!$H$28) -> 8.420905 | D17: =C17*(1+'1. Assumptions'!$I$28) -> 8.8419503 | E17: =D17*(1+'1. Assumptions'!$J$28) -> 9.2840478 | F17: =E17*(1+'1. Assumptions'!$K$28) -> 9.6554097 | G17: =F17*(1+'1. Assumptions'!$B$12) -> 9.8967949
A18: AFFO | B18: =B17*'8. FFO-AFFO'!$N$8*'1. Assumptions'!$B$38 -> 2418.8652 | C18: =C17*'8. FFO-AFFO'!$N$8*'1. Assumptions'!$B$38 -> 2563.9972 | D18: =D17*'8. FFO-AFFO'!$N$8*'1. Assumptions'!$B$38 -> 2692.197 | E18: =E17*'8. FFO-AFFO'!$N$8*'1. Assumptions'!$B$38 -> 2826.8069 | F18: =F17*'8. FFO-AFFO'!$N$8*'1. Assumptions'!$B$38 -> 2939.8791 | G18: =G17*'8. FFO-AFFO'!$N$8*'1. Assumptions'!$B$38 -> 3013.3761
A19: (-) Development capex | B19: =-'1. Assumptions'!G23 -> -800 | C19: =-'1. Assumptions'!H23 -> -1000 | D19: =-'1. Assumptions'!I23 -> -1200 | E19: =-'1. Assumptions'!J23 -> -1300 | F19: =-'1. Assumptions'!K23 -> -1100
A20: (+) Debt issuance (net) | B20: =-B19*'1. Assumptions'!$B$39 -> 400 | C20: =-C19*'1. Assumptions'!$B$39 -> 500 | D20: =-D19*'1. Assumptions'!$B$39 -> 600 | E20: =-E19*'1. Assumptions'!$B$39 -> 650 | F20: =-F19*'1. Assumptions'!$B$39 -> 550
A21: FCFE | B21: =B18+B19+B20 -> 2018.8652 | C21: =C18+C19+C20 -> 2063.9972 | D21: =D18+D19+D20 -> 2092.197 | E21: =E18+E19+E20 -> 2176.8069 | F21: =F18+F19+F20 -> 2389.8791
A22: Discount factor | B22: =1/(1+'1. Assumptions'!$B$31)^1 -> 0.90456807 | C22: =1/(1+'1. Assumptions'!$B$31)^2 -> 0.81824339 | D22: =1/(1+'1. Assumptions'!$B$31)^3 -> 0.74015684 | E22: =1/(1+'1. Assumptions'!$B$31)^4 -> 0.66952225 | F22: =1/(1+'1. Assumptions'!$B$31)^5 -> 0.60562845
A23: PV of FCFE | B23: =B21*B22 -> 1826.201 | C23: =C21*C22 -> 1688.852 | D23: =D21*D22 -> 1548.5539 | E23: =E21*E22 -> 1457.4206 | F23: =F21*F22 -> 1447.3788
A26: Terminal value (exit-cap on terminal AFFO) | G26: =G18/'1. Assumptions'!$B$35 -> 46359.633
A27: PV of terminal value | G27: =G26*F22 -> 28076.712
A28: Sum PV of explicit FCFE (2026-30) | B28: =SUM(B23:F23) -> 7968.4064
A29: (+) PV of terminal value | B29: =G27 -> 28076.712
A30: Equity value | B30: =B28+B29 -> 36045.119
A31: Diluted shares (M) | B31: ='8. FFO-AFFO'!$N$8 -> 346
A33: DCF VALUE PER SHARE | B33: =IFERROR(B30/B31,0) -> 104.17664
A34: FCFE = AFFO − dev capex + net debt issuance; discounted at cost of equity, so the PV sum is equity value (no further net-debt bridge).
A38: NAV VALUATION
A40: Forward 12M stabilized NOI by segment
A41: Segment | B41: NOI ($M) | C41: Cap rate | D41: GAV ($M)
A42: Hyperscale — Americas | B42: ='3. Segment Build'!G17 -> 1792.2 | C42: 0.065 | D42: =B42/C42 -> 27572.308
A43: Hyperscale — EMEA | B43: ='3. Segment Build'!G18 -> 1014.75 | C43: 0.065 | D43: =B43/C43 -> 15611.538
A44: Hyperscale — APAC | B44: ='3. Segment Build'!G19 -> 592.8 | C44: 0.07 | D44: =B44/C44 -> 8468.5714
A45: Colocation — global | B45: ='3. Segment Build'!G20 -> 373.32 | C45: 0.06 | D45: =B45/C45 -> 6222
A47: Gross Asset Value — operating | D47: =SUM(D42:D45) -> 57874.418
A48: NAV cash (D50) & debt (D51) link to Historicals; segment NOI (B42:B45) flows from Tab 3 (illustrative split — replace with 10-K segment NOI).
A49: (+) Development pipeline at cost | D49: ='4. Dev Pipeline'!F20 -> 280
A50: (+) Cash & equivalents | D50: ='2. Historicals'!F41 -> 0
A51: (-) Total debt (market value) | D51: ='2. Historicals'!F46 -> 18225
A52: (-) Preferred equity | D52: 755
A54: NAV | D54: =D47+D49+D50-D51-D52 -> 39174.418
A55: Diluted shares outstanding (M) | D55: ='8. FFO-AFFO'!$N$8 -> 346
A57: NAV PER SHARE | D57: =IFERROR(D54/D55,0) -> 113.22086
...

Sheet 10. Sensitivity
A1: Sensitivity Tables & Output Summary
A2: Two-way sensitivities on the most contested assumptions. Output summary feeds the memo PDF.
A4: Two-way tables below: build with Excel Data Table (Data → What-If → Data Table), row input = exit cap / cap rate, column input = WACC / SP-NOI growth, referencing the DCF (B33) & NAV (D57) outputs.
A7: SENSITIVITY 1: WACC × Terminal Cap Rate → DCF Value Per Share
A9: WACC \ Exit Cap | B9: 0.055 | C9: 0.06 | D9: 0.065 | E9: 0.07 | F9: 0.075
A10: 0.065 | B10: [link DCF output] | C10: [link DCF output] | D10: [link DCF output] | E10: [link DCF output] | F10: [link DCF output]
A11: 0.07 | B11: [link DCF output] | C11: [link DCF output] | D11: [link DCF output] | E11: [link DCF output] | F11: [link DCF output]
A12: 0.075 | B12: [link DCF output] | C12: [link DCF output] | D12: [link DCF output] | E12: [link DCF output] | F12: [link DCF output]
A13: 0.08 | B13: [link DCF output] | C13: [link DCF output] | D13: [link DCF output] | E13: [link DCF output] | F13: [link DCF output]
A14: 0.085 | B14: [link DCF output] | C14: [link DCF output] | D14: [link DCF output] | E14: [link DCF output] | F14: [link DCF output]
A19: SENSITIVITY 2: SP-NOI Growth × NAV Cap Rate → NAV Per Share
A21: SP-NOI Growth \ Cap Rate | B21: 0.055 | C21: 0.06 | D21: 0.065 | E21: 0.07 | F21: 0.075
A22: 0.02 | B22: [link NAV output] | C22: [link NAV output] | D22: [link NAV output] | E22: [link NAV output] | F22: [link NAV output]
A23: 0.03 | B23: [link NAV output] | C23: [link NAV output] | D23: [link NAV output] | E23: [link NAV output] | F23: [link NAV output]
A24: 0.04 | B24: [link NAV output] | C24: [link NAV output] | D24: [link NAV output] | E24: [link NAV output] | F24: [link NAV output]
A25: 0.05 | B25: [link NAV output] | C25: [link NAV output] | D25: [link NAV output] | E25: [link NAV output] | F25: [link NAV output]
A26: 0.06 | B26: [link NAV output] | C26: [link NAV output] | D26: [link NAV output] | E26: [link NAV output] | F26: [link NAV output]
A31: OUTPUT SUMMARY (for memo)
A33: Current price | B33: ='9. Valuation'!B66 -> 172.88
A34: DCF target | B34: ='9. Valuation'!B64 -> 104.17664
A35: NAV target | B35: ='9. Valuation'!B65 -> 113.22086
A36: Blended target | B36: ='9. Valuation'!B68 -> 108.69875
A37: Implied return | B37: ='9. Valuation'!B70 -> -0.37124739
A38: Recommendation | B38: ='9. Valuation'!B72 -> [Buy / Hold / Sell — your call, based on the model output + your thesis]
A40: Key thesis points | B40: [Paste 3-4 bullets here]
A41: Key risks | B41: [Paste 2-3 bullets here]
A42: Catalysts (next 12M) | B42: [Paste 3-5 bullets here]
